<?xml version="1.0"?>
<robot name="zoro">
    <link name="base_footprint"/>
    <material name="Yellow">
        <color rgba="0.5 0.5 0.0 1" />
      </material>
      <material name="Red">
        <color rgba="0.5 0.0 0.0 1" />
      </material>
      <material name="Blue">
        <color rgba="0.0 0.0 0.4 1" />
      </material>
      <material name="Green">
        <color rgba="0.0 0.4 0.0 1" />
      </material>
      <material name="Black">
        <color rgba="0.0 0 0.0 1" />
      </material>

      <link name="base_link">
        <inertial>
             <origin xyz="0.0 0.0 0.0" rpy="0 0 0"/>   
             <mass value="0.1"/>
             <inertia ixx="0.5" ixy="0.5" ixz="0.0000018" iyy="0.068406" iyz="-0.0049053" izz="0.12343" /> 
        </inertial>
        <visual>
         <origin xyz="0 0 0" rpy="0 0 0"/>   
         <geometry>    
            <box size="0.9 0.9 0.1"/>
         </geometry>
        </visual>
        <collision>
          <origin xyz="0 0 0" rpy="0 0 0"/>   
          <geometry>    
               <box size="0.9 0.9 0.1"/>
            </geometry>
        </collision>
    </link>

    <joint name="base_joint" type="fixed">
        <origin xyz="-0.5 0.5 0.15" rpy="0 0 0"/>   
        <parent link="base_footprint"/>
        <child link="base_link"/>
        <axis xyz="0.0 0.0 0.0"/>
    </joint>




    <link name="max_r1_link">
      <inertial>
           <origin xyz="0.0 0.0 0.0" rpy="0 0 0"/>   
           <mass value="0.100"/>
           <inertia ixx="0.079945" ixy="0.00012078" ixz="0.00015606" iyy="0.068406" iyz="-0.0049053" izz="0.12343" /> 
      </inertial>
      <visual>
       <origin xyz="0 0 0" rpy="0 0 0"/>   
       <geometry>    
          <box size="0.1 0.1 0.9"/>
       </geometry>
      </visual>
      <collision>
        <origin xyz="0 0 0" rpy="0 0 0"/>   
        <geometry>    
             <box size="0.1 0.1 0.9"/>
          </geometry>
      </collision>
  </link>

  <joint name="mzx_r1_joint" type="fixed">
      <origin xyz="-0.9 0.1 0.65" rpy="0 0 0"/>   
      <parent link="base_footprint"/>
      <child link="max_r1_link"/>
      <axis xyz="0.0 0.0 0.0"/>
  </joint>


  <link name="max_r2_link">
    <inertial>
         <origin xyz="0.0 0.0 0.0" rpy="0 0 0"/>   
         <mass value="0.1"/>
         <inertia ixx="0.079945" ixy="0.00012078" ixz="0.00015606" iyy="0.068406" iyz="-0.0049053" izz="0.12343" /> 
    </inertial>
    <visual>
     <origin xyz="0 0 0" rpy="0 0 0"/>   
     <geometry>    
        <box size="0.1 0.1 0.9"/>
     </geometry>
    </visual>
    <collision>
      <origin xyz="0 0 0" rpy="0 0 0"/>   
      <geometry>    
           <box size="0.1 0.1 0.9"/>
        </geometry>
    </collision>
</link>

<joint name="max_r2_joint" type="fixed">
    <origin xyz="-0.9 0.9 0.65" rpy="0 0 0"/>   
    <parent link="base_footprint"/>
    <child link="max_r2_link"/>
    <axis xyz="0.0 0.0 0.0"/>
</joint>

<link name="max_r3_link">
  <inertial>
       <origin xyz="0.0 0.0 0.0" rpy="0 0 0"/>   
       <mass value="0.1"/>
       <inertia ixx="0.079945" ixy="0.00012078" ixz="0.00015606" iyy="0.068406" iyz="-0.0049053" izz="0.12343" /> 
  </inertial>
  <visual>
   <origin xyz="0 0 0" rpy="0 0 0"/>   
   <geometry>    
      <box size="0.1 0.1 0.9"/>
   </geometry>
  </visual>
  <collision>
    <origin xyz="0 0 0" rpy="0 0 0"/>   
    <geometry>    
         <box size="0.1 0.1 0.9"/>
      </geometry>
  </collision>
</link>

<joint name="max_r3_joint" type="fixed">
  <origin xyz="-0.1 0.9 0.65" rpy="0 0 0"/>   
  <parent link="base_footprint"/>
  <child link="max_r3_link"/>
  <axis xyz="0.0 0.0 0.0"/>
</joint>


<link name="max_r4_link">
  <inertial>
       <origin xyz="0.0 0.0 0.0" rpy="0 0 0"/>   
       <mass value="0.1"/>
       <inertia ixx="0.079945" ixy="0.00012078" ixz="0.00015606" iyy="0.068406" iyz="-0.0049053" izz="0.12343" /> 
  </inertial>
  <visual>
   <origin xyz="0 0 0" rpy="0 0 0"/>   
   <geometry>    
    <box size="0.1 0.1 0.9"/>
  </geometry>
  </visual>
  <collision>
    <origin xyz="0 0 0" rpy="0 0 0"/>   
    <geometry>    
      <box size="0.1 0.1 0.9"/>
    </geometry>
  </collision>
</link>

<joint name="max_r4_joint" type="fixed">
  <origin xyz="-0.1 0.1 0.65" rpy="0 0 0"/>   
  <parent link="base_footprint"/>
  <child link="max_r4_link"/>
  <axis xyz="0.0 0.0 0.0"/>
</joint>

<!-- min rods for battery and buck convertor holder -->

<link name="min_r1_link">
  <inertial>
       <origin xyz="0.0 0.0 0.0" rpy="0 0 0"/>   
       <mass value="0.05"/>
       <inertia ixx="0.079945" ixy="0.00012078" ixz="0.00015606" iyy="0.068406" iyz="-0.0049053" izz="0.12343" /> 
  </inertial>
  <visual>
    <material name="Red">
    </material>
   <origin xyz="0 0 0" rpy="0 0 0"/>   
   <geometry>    
    <box size="0.1 0.1 0.45"/>
  </geometry>
  </visual>
  <collision>
    <origin xyz="0 0 0" rpy="0 0 0"/>   
    <geometry>    
      <box size="0.1 0.1 0.45"/>
    </geometry>
  </collision>
</link>

<joint name="min_r1_joint" type="fixed">
  <origin xyz="-0.9 0.7 0.425" rpy="0 0 0"/>   
  <parent link="base_footprint"/>
  <child link="min_r1_link"/>
  <axis xyz="0.0 0.0 0.0"/>
</joint>


<link name="min_r2_link">
  <inertial>
       <origin xyz="0.0 0.0 0.0" rpy="0 0 0"/>   
       <mass value="0.05"/>
       <inertia ixx="0.079945" ixy="0.00012078" ixz="0.00015606" iyy="0.068406" iyz="-0.0049053" izz="0.12343" /> 
  </inertial>
  <visual>
    <material name="Red">
    </material>
   <origin xyz="0 0 0" rpy="0 0 0"/>   
   <geometry>    
    <box size="0.1 0.1 0.45"/>
  </geometry>
  </visual>
  <collision>
    <origin xyz="0 0 0" rpy="0 0 0"/>   
    <geometry>    
      <box size="0.1 0.1 0.45"/>
    </geometry>
  </collision>
</link>

<joint name="min_r2_joint" type="fixed">
  <origin xyz="-0.9 0.3 0.425" rpy="0 0 0"/>   
  <parent link="base_footprint"/>
  <child link="min_r2_link"/>
  <axis xyz="0.0 0.0 0.0"/>
</joint>

<link name="min_r3_link">
  <inertial>
       <origin xyz="0.0 0.0 0.0" rpy="0 0 0"/>   
       <mass value="0.05"/>
       <inertia ixx="0.079945" ixy="0.00012078" ixz="0.00015606" iyy="0.068406" iyz="-0.0049053" izz="0.12343" /> 
  </inertial>
  <visual>
    <material name="Red">
    </material>
   <origin xyz="0 0 0" rpy="0 0 0"/>   
   <geometry>    
    <box size="0.1 0.1 0.45"/>
  </geometry>
  </visual>
  <collision>
    <origin xyz="0 0 0" rpy="0 0 0"/>   
    <geometry>    
      <box size="0.1 0.1 0.45"/>
    </geometry>
  </collision>
</link>

<joint name="min_r3_joint" type="fixed">
  <origin xyz="-0.1 0.7 0.425" rpy="0 0 0"/>   
  <parent link="base_footprint"/>
  <child link="min_r3_link"/>
  <axis xyz="0.0 0.0 0.0"/>
</joint>

<link name="min_r4_link">
  <inertial>
       <origin xyz="0.0 0.0 0.0" rpy="0 0 0"/>   
       <mass value="0.05"/>
       <inertia ixx="0.079945" ixy="0.00012078" ixz="0.00015606" iyy="0.068406" iyz="-0.0049053" izz="0.12343" /> 
  </inertial>
  <visual>
    <material name="Red">
    </material>
   <origin xyz="0 0 0" rpy="0 0 0"/>   
   <geometry>    
    <box size="0.1 0.1 0.45"/>
  </geometry>
  </visual>
  <collision>
    <origin xyz="0 0 0" rpy="0 0 0"/>   
    <geometry>    
      <box size="0.1 0.1 0.45"/>
    </geometry>
  </collision>
</link>

<joint name="min_r4_joint" type="fixed">
  <origin xyz="-0.1 0.3 0.425" rpy="0 0 0"/>   
  <parent link="base_footprint"/>
  <child link="min_r4_link"/>
  <axis xyz="0.0 0.0 0.0"/>
</joint>


<!-- base and top plates -->



<link name="base_plate_link">
  <inertial>
       <origin xyz="0.0 0.0 0.0" rpy="0 0 0"/>   
       <mass value="0.5"/>
       <inertia ixx="0.079945" ixy="0.00012078" ixz="0.00015606" iyy="0.068406" iyz="-0.0049053" izz="0.12343" /> 
  </inertial>
  <visual>
    <material name="Red">
    </material>
   <origin xyz="0 0 0" rpy="0 0 0"/>   
   <geometry>    
    <box size="0.9 0.49 0.03"/>
  </geometry>
  </visual>
  <collision>
    <origin xyz="0 0 0" rpy="0 0 0"/>   
    <geometry>    
      <box size="1 0.5 0.03"/>
    </geometry>
  </collision>
</link>

<joint name="base_plate_joint" type="fixed">
  <origin xyz="-0.5 0.5 0.65" rpy="0 0 0"/>   
  <parent link="base_footprint"/>
  <child link="base_plate_link"/>
  <axis xyz="0.0 0.0 0.0"/>
</joint>


<link name="top_plate_link">
  <inertial>
       <origin xyz="0.0 0.0 0.0" rpy="0 0 0"/>   
       <mass value="1"/>
       <inertia ixx="0.079945" ixy="0.00012078" ixz="0.00015606" iyy="0.068406" iyz="-0.0049053" izz="0.12343" /> 
  </inertial>
  <visual>
    <material name="Red">
    </material>
   <origin xyz="0 0 0" rpy="0 0 0"/>   
   <geometry>    
    <box size="0.9 0.9 0.03"/>
  </geometry>
  </visual>
  <collision>
    <origin xyz="0 0 0" rpy="0 0 0"/>   
    <geometry>    
      <box size="0.9 0.9 0.03"/>
    </geometry>
  </collision>
</link>

<joint name="top_plate_joint" type="fixed">
  <origin xyz="-0.5 0.5 1.1" rpy="0 0 0"/>   
  <parent link="base_footprint"/>
  <child link="top_plate_link"/>
  <axis xyz="0.0 0.0 0.0"/>
</joint>


<!-- lidar link -->



<link name="laser">
  <visual>
  <origin rpy="0 0 0" xyz="0 0 0"/>
  <geometry>
    <mesh filename="package://zoro_description/meshes/RpLidar.stl" scale="0.004 0.004 0.004"/>
  </geometry>
  <material name="Black"/>
  </visual>
  <collision>
  <origin rpy="0 0 0" xyz="0 0 0"  />
  <geometry>
    <mesh filename="package://zoro_description/meshes/RpLidar.stl" scale="0.004 0.004 0.004"/>
  </geometry>
  </collision>
  </link>  
  
  <joint name="laser_joint" type="fixed">
    <origin xyz="-0.3 0.95 0.7" rpy="0 0 1.5708" />
    <parent link="base_link" />
    <child link="laser" />
  </joint>
  









<!-- _____________________________________wheels____________________________________________________ -->












<!-- _______________________omni direction side wheels______________________________ -->

<link name="wheel2_link">
  <inertial>
    <origin xyz="0.0 0.0 0.0" rpy="0 0 0" />
    <mass value="0.50917" />
    <inertia ixx="0.0012185" ixy="1.8059E-20" ixz="3.0427E-20" iyy="0.0012185" iyz="-4.0491E-20" izz="0.0022928" />
  </inertial>
  <visual>
    <origin xyz="0 0 0" rpy="0 1.5708 0" />
<geometry>
  <mesh filename="package://zoro_description/meshes/body.stl" scale="0.008 0.008 0.008"/>
</geometry>      
    <material name="Red" />
  </visual>
  <collision>
    <origin xyz="0 0 0" rpy="0 1.5708 0" />
      <geometry>
        <mesh filename="package://zoro_description/meshes/body.stl" scale="0.008 0.008 0.008"/>
    </geometry>
  </collision>
</link>

<joint name="wheel2_joint" type="continuous">
  <origin xyz="-0.04 0.5 0.15" rpy="0 0 0" />
  <parent link="base_footprint" />
  <child link="wheel2_link" />
  <axis xyz="0 0 0" />
</joint>




<link name="wheel4_link">
  <inertial>
    <origin xyz="0.0 0.0 0.0" rpy="0 0 0" />
    <mass value="0.50917" />
    <inertia ixx="0.0012185" ixy="1.8059E-20" ixz="3.0427E-20" iyy="0.0012185" iyz="-4.0491E-20" izz="0.0022928" />
  </inertial>
  <visual>
    <origin xyz="0 0 0" rpy="0 1.5708 0" />
<geometry>
  <mesh filename="package://zoro_description/meshes/body.stl" scale="0.008 0.008 0.008"/>
</geometry>      
    <material name="Red"/>
  </visual>
  <collision>
    <origin xyz="0 0 0" rpy="0 1.5708 0" />
      <geometry>
        <mesh filename="package://zoro_description/meshes/body.stl" scale="0.008 0.008 0.008"/>
    </geometry>
  </collision>
</link>

<joint name="wheel4_joint" type="continuous">
  <origin xyz="-1.12 0.5 0.15" rpy="1.5708 0 0" />
  <parent link="base_footprint" />
  <child link="wheel4_link" />
  <axis xyz="0 0 0" />
</joint>



<!-- _____________________________________omni directional forward direction_____________________________________________________ -->


<!-- ________________________________________________ -->


<!-- <link name="wheel1_link">
  <inertial>
    <origin xyz="0.0 0.0 0.0" rpy="0 0 0" />
    <mass value="0.50917" />
    <inertia ixx="0.0012185" ixy="1.8059E-20" ixz="3.0427E-20" iyy="0.0012185" iyz="-4.0491E-20" izz="0.0022928" />
  </inertial>
  <visual>
    <origin xyz="0 0 0" rpy="1.5708 0 0" />
    <geometry>
      <mesh filename="package://zoro_description/meshes/body.stl" scale="0.008 0.008 0.008"/>
    </geometry>
    <material name="Blue" />
  </visual>
  <collision>
    <origin xyz="0 0 0" rpy="1.5708 0 0" />
      <geometry>
        <mesh filename="package://zoro_description/meshes/body.stl" scale="0.008 0.008 0.008"/>
      </geometry>
  </collision>
</link> -->


<!-- <joint name="wheel1_joint" type="continuous">
<origin xyz="-0.5 0.036 0.15" rpy="0 0 0" />
<parent link="base_footprint" />
<child link="wheel1_link" />
<axis xyz="0 0 0" />
</joint> -->

<link name="wheel1_link">
  <inertial>
    <origin xyz="0.0 0.0 0.0" rpy="0 0 0" />
    <mass value="0.50917" />
    <inertia ixx="0.0012185" ixy="1.8059E-20" ixz="3.0427E-20" iyy="0.0012185" iyz="-4.0491E-20" izz="0.0022928" />
  </inertial>
  <visual>
    <origin xyz="0 0 0" rpy="1.5708 0 0" />
<geometry>
  <mesh filename="package://zoro_description/meshes/body.stl" scale="0.008 0.008 0.008"/>
</geometry>      
    <material name="Red" />
  </visual>
  <collision>
    <origin xyz="0 0 0" rpy="1.5708 0 0" />
      <geometry>
        <mesh filename="package://zoro_description/meshes/body.stl" scale="0.008 0.008 0.008"/>
    </geometry>
  </collision>
</link>

<joint name="wheel1_joint" type="continuous">
  <origin xyz="-0.5 0.036 0.15" rpy="0 0 0" />
  <parent link="base_footprint" />
  <child link="wheel1_link" />
  <axis xyz="0 0 0" />
</joint>


<!-- <link name="wheel3_link">
  <inertial>
    <origin xyz="0.0 0.0 0.0" rpy="0 0 0" />
    <mass value="0.50917" />
    <inertia ixx="0.0012185" ixy="1.8059E-20" ixz="3.0427E-20" iyy="0.0012185" iyz="-4.0491E-20" izz="0.0022928" />
  </inertial>
  <visual>
    <origin xyz="0 0 0" rpy="1.5708 0 0" />
    <geometry>
      <mesh filename="package://zoro_description/meshes/body.stl" scale="0.008 0.008 0.008"/>
    </geometry>
    <material name="Blue" />
  </visual>
  <collision>
    <origin xyz="0 -0.03 0" rpy="1.5708 0 0" />
      <geometry>
        <mesh filename="package://zoro_description/meshes/body.stl" scale="0.008 0.008 0.008"/>
      </geometry>
  </collision>
</link>

<joint name="wheel3_joint" type="continuous">
<origin xyz="-0.5 1.12 0.15" rpy="0 0 0" />
<parent link="base_footprint" />
<child link="wheel3_link" />
<axis xyz="0 0 0" />
</joint> -->

<link name="wheel3_link">
  <inertial>
    <origin xyz="0.0 0.0 0.0" rpy="0 0 0" />
    <mass value="0.50917" />
    <inertia ixx="0.0012185" ixy="1.8059E-20" ixz="3.0427E-20" iyy="0.0012185" iyz="-4.0491E-20" izz="0.0022928" />
  </inertial>
  <visual>
    <origin xyz="0 0 0" rpy="1.5708 0 0" />
<geometry>
  <mesh filename="package://zoro_description/meshes/body.stl" scale="0.008 0.008 0.008"/>
</geometry>      
    <material name="Red" />
  </visual>
  <collision>
    <origin xyz="0 0 0" rpy="1.5708 0 0" />
      <geometry>
        <mesh filename="package://zoro_description/meshes/body.stl" scale="0.008 0.008 0.008"/>
    </geometry>
  </collision>
</link>

<joint name="wheel3_joint" type="continuous">
  <origin xyz="-0.5 1.12 0.15" rpy="0 0 0" />
  <parent link="base_footprint" />
  <child link="wheel3_link" />
  <axis xyz="0 0 0" />
</joint>



<gazebo>
    <plugin name="gazebo_ros_control" filename="libgazebo_ros_control.so">
<updateRate>10</updateRate>
<!-- Name of left joint, defaults to `left_joint` -->
<leftJoint>wheel2_joint</leftJoint>
<rearleftJoint>wheel1_joint</rearleftJoint>                  
<!-- Name of right joint, defaults to `right_joint` -->
<rearrightJoint>wheel3_joint</rearrightJoint>
<rightJoint>wheel4_joint</rightJoint>
<!-- The distance from the center of one wheel to the other, in meters, defaults to 0.34 m -->
<wheelSeparation>0.25</wheelSeparation>
<!-- Diameter of the wheels, in meters, defaults to 0.15 m -->
<wheelDiameter>0.1</wheelDiameter>
<!-- Wheel acceleration, in rad/s^2, defaults to 0.0 rad/s^2 -->
<wheelAcceleration>20</wheelAcceleration>
<!-- Maximum torque which the wheels can produce, in Nm, defaults to 5 Nm -->
<wheelTorque>15</wheelTorque>
<!-- Topic to receive geometry_msgs/Twist message commands, defaults to `cmd_vel` -->
<commandTopic>zoro_velocity</commandTopic>
<!-- Topic to publish nav_msgs/Odometry messages, defaults to `odom` -->
<odometryTopic>odometry_z</odometryTopic>
<!-- Odometry frame, defaults to `odom` -->
<odometryFrame>odometry</odometryFrame>
<!-- Robot frame to calculate odometry from, defaults to `base_footprint` -->
<robotBaseFrame>base_footprint</robotBaseFrame>
<!-- Odometry source, 0 for ENCODER, 1 for WORLD, defaults to WORLD -->
<odometrySource>1</odometrySource>
<!-- Set to true to publish transforms for the wheel links, defaults to false -->
<publishWheelTF>false</publishWheelTF>
<!-- Set to true to publish transforms for the odometry, defaults to true -->
<publishOdom>True</publishOdom>
<!-- Set to true to publish sensor_msgs/JointState on /joint_states for the wheel joints, defaults to false -->
<publishWheelJointState>true</publishWheelJointState>
<!-- Set to true to swap right and left wheels, defaults to true -->
<legacyMode>false</legacyMode>
</plugin>
</gazebo>

</robot>